<mujoco model="iris">/////////////////////////
    <compiler angle="radian" meshdir="../meshes/" />
    <size njmax="500" nconmax="100" />
    <asset>
        <mesh name="iris" file="iris.stl" />
        <mesh name="propeller_ccw" file="propeller_ccw.stl" scale="0.1 0.1 0.1" />
        <mesh name="propeller_cw" file="propeller_cw.stl" scale="0.1 0.1 0.1" />
        
        <texture type="skybox" builtin="gradient" rgb1=".4 .5 .6" rgb2="0 0 0" width="100" height="100"/>
    	<texture builtin="flat" height="1278" mark="cross" markrgb="1 1 1" name="texgeom" random="0.01" rgb1="0.8 0.6 0.4" rgb2="0.8 0.6 0.4" type="cube" width="127"/>
    	<texture builtin="checker" height="100" name="texplane" rgb1="0 0 0" rgb2="0.8 0.8 0.8" type="2d" width="100"/>
    	<material name="MatPlane" reflectance="0.5" shininess="1" specular="1" texrepeat="60 60" texture="texplane"/>
    	<material name="geom" texture="texgeom" texuniform="true"/>
    	<texture name="grid_new" type="2d" builtin="checker" rgb1=".1 .3 .2" rgb2=".2 .4 .3" width="1000" height="1000" mark="none" markrgb=".8 .6 .4"/>
    	<material name="grid_new" texture="grid_new" texrepeat="0.2 0.2" texuniform="true" reflectance=".2"/>
    </asset>

    <worldbody>
        <geom type="mesh" contype="0" conaffinity="0" group="1" mesh="iris" />
        <geom size="0.235 0.235 0.055" type="box" />
        <geom size="0.009 0.1" pos="0.13 -0.22 -0.102" type="cylinder" contype="0" conaffinity="0" group="1" rgba="0 0 0.8 1" />
        <geom size="0.009 0.1" pos="0.13 -0.22 0.023" type="cylinder" rgba="0 0 0.8 1" />
        <geom size="0.009 0.1" pos="-0.13 0.2 -0.102" type="cylinder" contype="0" conaffinity="0" group="1" rgba="0 0 0.8 1" />
        <geom size="0.009 0.1" pos="-0.13 0.2 0.023" type="cylinder" rgba="0 0 0.8 1" />
        <geom size="0.009 0.1" pos="0.13 0.22 -0.102" type="cylinder" contype="0" conaffinity="0" group="1" rgba="0 0 0.8 1" />
        <geom size="0.009 0.1" pos="0.13 0.22 0.023" type="cylinder" rgba="0 0 0.8 1" />
        <geom size="0.009 0.1" pos="-0.13 -0.2 -0.102" type="cylinder" contype="0" conaffinity="0" group="1" rgba="0 0 0.8 1" />
        <geom size="0.009 0.1" pos="-0.13 -0.2 0.023" type="cylinder" rgba="0 0 0.8 1" />
        <body name="iris/rotor_0" pos="0.13 -0.22 0.023">
            <inertial pos="0 0 0" quat="0 0.707107 0 0.707107" mass="0.005" diaginertia="4.26041e-05 4.17041e-05 9.75e-07" />
            <joint name="iris/rotor_0_joint" pos="0 0 0" axis="0 0 1" />
            <geom type="mesh" contype="0" conaffinity="0" group="1" mesh="propeller_ccw" />
            <geom size="0.1 0.0025" type="cylinder" />
        </body>
        <body name="iris/rotor_1" pos="-0.13 0.2 0.023">
            <inertial pos="0 0 0" quat="0 0.707107 0 0.707107" mass="0.005" diaginertia="4.26041e-05 4.17041e-05 9.75e-07" />
            <joint name="iris/rotor_1_joint" pos="0 0 0" axis="0 0 1" />
            <geom type="mesh" contype="0" conaffinity="0" group="1" mesh="propeller_ccw" />
            <geom size="0.1 0.0025" type="cylinder" />
        </body>
        <body name="iris/rotor_2" pos="0.13 0.22 0.023">
            <inertial pos="0 0 0" quat="0 0.707107 0 0.707107" mass="0.005" diaginertia="4.26041e-05 4.17041e-05 9.75e-07" />
            <joint name="iris/rotor_2_joint" pos="0 0 0" axis="0 0 1" />
            <geom type="mesh" contype="0" conaffinity="0" group="1" mesh="propeller_cw" />
            <geom size="0.1 0.0025" type="cylinder" />
        </body>
        <body name="iris/rotor_3" pos="-0.13 -0.2 0.023">
            <inertial pos="0 0 0" quat="0 0.707107 0 0.707107" mass="0.005" diaginertia="4.26041e-05 4.17041e-05 9.75e-07" />
            <joint name="iris/rotor_3_joint" pos="0 0 0" axis="0 0 1" />
            <geom type="mesh" contype="0" conaffinity="0" group="1" mesh="propeller_cw" />
            <geom size="0.1 0.0025" type="cylinder" />
        </body>
    </worldbody>
</mujoco>
