<mujoco model="10">
    <include file="../../common/skybox.xml"/>
    <include file="../../common/visual.xml"/>
    <include file="../../common/materials.xml"/>

    <option timestep=".005"/>

    <compiler angle="degree" meshdir="." />
    <asset>
        <mesh name="part" file="part.STL" scale="0.01 0.01 0.01"/>
    </asset>

    <worldbody>
        <light name="light" pos="0 0 2"/>
        <geom name="floor" size="20 20 .2" type="plane" material="grid"/>
        <camera name="fixed" pos="0 -1.5 2" xyaxes='1 0 0 0 1 1'/>
        <body name="base" pos="0 0 0.6">
            <joint name="joint0" type="free" />
            <geom name="link0" type="mesh" mesh="part" pos="0 0 0" rgba=".97 0.578 0.0625 0.8" euler="-90 0 45" mass="1"/>
            <body name="link1" pos="-0.55 1 -0.55" euler="90 0 45">
                <geom name="link1" type="mesh" mesh="part" rgba="1 1 1 1" mass="1"/>
                <joint name="joint1" axis="0 45 0" pos="0.35 -0.1 0.5" type="hinge"/>
                <body name="link2" pos="0 0.778 0" euler="0 0 180">
                    <geom name="link2" type="mesh" mesh="part" rgba=".97 0.578 0.0625 0.8" mass="1"/>
                    <joint name="joint2" axis="-45 0 0" pos="0.1 0.45 0.5" type="hinge"/>
                    <body name="link3" pos="0.778 0 0" euler="0 0 180">
                        <geom name="link3" type="mesh" mesh="part" rgba="1 1 1 1" mass="1"/>
                        <joint name="joint3" axis="0 45 0" pos="0.35 -0.1 0.5" type="hinge"/>
                        <body name="link4" pos="0 0.778 0" euler="0 0 180">
                            <geom name="link4" type="mesh" mesh="part" rgba=".97 0.578 0.0625 0.8" mass="1"/>
                            <joint name="joint4" axis="-45 0 0" pos="0.1 0.45 0.5" type="hinge"/>
                            <body name="link5" pos="0.778 0 0" euler="0 0 180">
                                <geom name="link5" type="mesh" mesh="part" rgba="1 1 1 1" mass="1"/>
                                <joint name="joint5" axis="0 45 0" pos="0.35 -0.1 0.5" type="hinge"/>
                                <body name="link6" pos="0 0.778 0" euler="0 0 180">
                                    <geom name="link6" type="mesh" mesh="part" rgba=".97 0.578 0.0625 0.8" mass="1"/>
                                    <joint name="joint6" axis="-45 0 0" pos="0.1 0.45 0.5" type="hinge"/>
                                    <body name="link7" pos="0.778 0 0" euler="0 0 180">
                                        <geom name="link7" type="mesh" mesh="part" rgba="1 1 1 1" mass="1"/>
                                        <joint name="joint7" axis="0 45 0" pos="0.35 -0.1 0.5" type="hinge"/>
                                        <body name="link8" pos="0 0.778 0" euler="0 0 180">
                                            <geom name="link8" type="mesh" mesh="part" rgba=".97 0.578 0.0625 0.8" mass="1"/>
                                            <joint name="joint8" axis="-45 0 0" pos="0.1 0.45 0.5" type="hinge"/>
                                            <body name="link9" pos="0.778 0 0" euler="0 0 180">
                                                <geom name="link9" type="mesh" mesh="part" rgba="1 1 1 1" mass="1"/>
                                                <joint name="joint9" axis="0 45 0" pos="0.35 -0.1 0.5" type="hinge"/>
                                            </body>
                                        </body>
                                    </body>
                                </body>
                            </body>
                        </body>
                    </body>
                </body>
            </body>

        </body>
    </worldbody>
</mujoco>